<mujoco model="ur10">
    <compiler angle="radian" meshdir="meshes/collision/" coordinate="local" inertiafromgeom='auto' texturedir="textures"/>
    <option timestep="0.01" apirate="200" iterations="20" noslip_iterations="20" tolerance="1e-10" impratio="10"
			gravity="0 0 -9.81" solver="PGS" cone="elliptic" />
<!--    <size njmax="500" nconmax="100" />-->
    <asset>
        <mesh name="base" file="base.stl" />
        <mesh name="shoulder" file="shoulder.stl" />
        <mesh name="upperarm" file="upperarm.stl" />
        <mesh name="forearm" file="forearm.stl" />
        <mesh name="wrist1" file="wrist1.stl" />
        <mesh name="wrist2" file="wrist2.stl" />
        <mesh name="wrist3" file="wrist3.stl" />
    </asset>
    <worldbody>
        <geom type="mesh" contype="0" conaffinity="0" group="1" rgba="0.7 0.7 0.7 1" mesh="base" />
        <geom type="mesh" rgba="0.7 0.7 0.7 1" mesh="base" />
        <body name="shoulder_link" pos="0 0 0.1273">
            <inertial pos="0 0 0" mass="7.778" diaginertia="0.0314743 0.0314743 0.0218756" />
            <joint name="shoulder_pan_joint" pos="0 0 0" axis="0 0 1" limited="true" range="-6.28319 6.28319" />
            <geom type="mesh" contype="0" conaffinity="0" group="1" rgba="0.7 0.7 0.7 1" mesh="shoulder" />
            <geom type="mesh" rgba="0.7 0.7 0.7 1" mesh="shoulder" />
            <body name="upper_arm_link" pos="0 0.220941 0" quat="0.707107 0 0.707107 0">
                <inertial pos="0 -0.045 0.306" mass="12.93" diaginertia="0.421754 0.421754 0.0363656" />
                <joint name="shoulder_lift_joint" pos="0 0 0" axis="0 1 0" limited="true" range="-6.28319 6.28319" />
                <geom type="mesh" contype="0" conaffinity="0" group="1" rgba="0.7 0.7 0.7 1" mesh="upperarm" />
                <geom type="mesh" rgba="0.7 0.7 0.7 1" mesh="upperarm" />
                <body name="forearm_link" pos="0 -0.1719 0.612">
                    <inertial pos="0 0 0.28615" mass="3.87" diaginertia="0.11107 0.11107 0.0108844" />
                    <joint name="elbow_joint" pos="0 0 0" axis="0 1 0" limited="true" range="-3.14159 3.14159" />
                    <geom type="mesh" contype="0" conaffinity="0" group="1" rgba="0.7 0.7 0.7 1" mesh="forearm" />
                    <geom type="mesh" rgba="0.7 0.7 0.7 1" mesh="forearm" />
                    <body name="wrist_1_link" pos="0 0 0.5723" quat="0.707107 0 0.707107 0">
                        <inertial pos="0 0.1149 0" quat="0.5 0.5 -0.5 0.5" mass="1.96" diaginertia="0.0055125 0.00510825 0.00510825" />
                        <joint name="wrist_1_joint" pos="0 0 0" axis="0 1 0" limited="true" range="-6.28319 6.28319" />
                        <geom type="mesh" contype="0" conaffinity="0" group="1" rgba="0.7 0.7 0.7 1" mesh="wrist1" />
                        <geom type="mesh" rgba="0.7 0.7 0.7 1" mesh="wrist1" />
                        <body name="wrist_2_link" pos="0 0.1149 0">
                            <inertial pos="0 0 0.1157" quat="0.5 0.5 -0.5 0.5" mass="1.96" diaginertia="0.0055125 0.00510825 0.00510825" />
                            <joint name="wrist_2_joint" pos="0 0 0" axis="0 0 1" limited="true" range="-6.28319 6.28319" />
                            <geom type="mesh" contype="0" conaffinity="0" group="1" rgba="0.7 0.7 0.7 1" mesh="wrist2" />
                            <geom type="mesh" rgba="0.7 0.7 0.7 1" mesh="wrist2" />
                            <body name="wrist_3_link" pos="0 0 0.1157">
                                <inertial pos="0 0.0769759 0" quat="0.707107 0 0 0.707107" mass="0.203" diaginertia="0.000204542 0.000117966 0.000117966" />
                                <joint name="wrist_3_joint" pos="0 0 0" axis="0 1 0" limited="true" range="-6.28319 6.28319" />
                                <geom type="mesh" contype="0" conaffinity="0" group="1" rgba="0.7 0.7 0.7 1" mesh="wrist3" />
                                <geom type="mesh" rgba="0.7 0.7 0.7 1" mesh="wrist3" />
                                <geom size="0.005 0.005 0.005" pos="0 0.0822 0" quat="0.707107 0 0 0.707107" type="box" />
                            </body>
                        </body>
                    </body>
                </body>
            </body>
        </body>
    </worldbody>
</mujoco>
